<?xml version="1.0" ?>
<robot name="converted_robot">
   <!--generated with mjcf_urdf_simple_converter (https://github.com/Yasu31/mjcf_urdf_simple_converter)-->
   <material name="Black">
      <color rgba="0.0 0.0 0.0 1.0"/>
   </material>
   <material name="Blue">
      <color rgba="0.0 0.0 0.8 1.0"/>
   </material>
   <material name="Green">
      <color rgba="0.0 0.8 0.0 1.0"/>
   </material>
   <material name="Grey">
      <color rgba="0.4 0.4 0.4 1.0"/>
   </material>
   <material name="Orange">
      <color rgba="1.0 0.423529411765 0.0392156862745 1.0"/>
   </material>
   <material name="Brown">
      <color rgba="0.870588235294 0.811764705882 0.764705882353 1.0"/>
   </material>
   <material name="Red">
      <color rgba="0.8 0.0 0.0 1.0"/>
   </material>
   <material name="White">
      <color rgba="1.0 1.0 1.0 1.0"/>
   </material>
   <material name="Collision">
      <color rgba="0.0 0.0 0.2 1.0"/>
   </material>
   <link name="Base">
      <inertial>
         <origin xyz="0.0 0.0 0.0" rpy="0.0 0.0 0.0"/>
         <mass value="0.0"/>
         <inertia ixx="0.0" iyy="0.0" izz="0.0" ixy="0" ixz="0" iyz="0"/>
      </inertial>
   </link>
   <link name="base">
      <inertial>
         <origin xyz="-0.1 0.0 0.07" rpy="0.0 0.0 0.0"/>
         <mass value="5.0"/>
         <inertia ixx="0.05" iyy="0.06" izz="0.03" ixy="0" ixz="0" iyz="0"/>
      </inertial>
      <visual name="link_0">
         <origin xyz="-0.012611671227004495 -3.254096985673413e-07 0.07039070638127487" rpy="-3.1406330260149353 -1.493081198161372 -0.0008898552412448524"/>
         <geometry>
            <mesh filename="meshes/converted_link_0_808080ff.obj"/>
         </geometry>
         <material name="Grey">
            <color rgba="0.4 0.4 0.4 1.0"/>
         </material>
      </visual>
      <collision name="link_0_col">
         <origin xyz="-0.012611671227004495 -3.254096985673413e-07 0.07039070638127487" rpy="-3.1406330260149353 -1.493081198161372 -0.0008898552412448524"/>
         <geometry>
            <mesh filename="meshes/converted_link_0_808080ff.obj"/>
         </geometry>
         <material name="Collision">
            <color rgba="0.0 0.0 0.2 1.0"/>
         </material>
      </collision>
   </link>
   <joint type="fixed" name="world2base_fixed">
      <parent link="Base"/>
      <child link="base"/>
      <origin xyz="0.0 0.0 0.0" rpy="0.0 0.0 0.0"/>
   </joint>
   <link name="link1">
      <inertial>
         <origin xyz="0.0 -0.03 0.12" rpy="0.0 0.0 0.0"/>
         <mass value="5.76"/>
         <inertia ixx="0.0333" iyy="0.033" izz="0.0123" ixy="0" ixz="0" iyz="0"/>
      </inertial>
      <visual name="link_1">
         <origin xyz="-1.9467006956065573e-06 -0.03351071875139483 0.12307399450484058" rpy="-5.6995778251800466e-05 -0.2150438000144541 1.5709677059154576"/>
         <geometry>
            <mesh filename="meshes/converted_link_1_808080ff.obj"/>
         </geometry>
         <material name="Grey">
            <color rgba="0.4 0.4 0.4 1.0"/>
         </material>
      </visual>
      <collision name="link_1_col">
         <origin xyz="-1.9467006956065573e-06 -0.03351071875139483 0.12307399450484058" rpy="-5.6995778251800466e-05 -0.2150438000144541 1.5709677059154576"/>
         <geometry>
            <mesh filename="meshes/converted_link_1_808080ff.obj"/>
         </geometry>
         <material name="Collision">
            <color rgba="0.0 0.0 0.2 1.0"/>
         </material>
      </collision>
   </link>
   <link name="joint1_jointbody">
      <inertial>
         <origin xyz="0.0 0.0 0.0" rpy="0.0 0.0 0.0"/>
         <mass value="0.001"/>
         <inertia ixx="1e-09" iyy="1e-09" izz="1e-09" ixy="0" ixz="0" iyz="0"/>
      </inertial>
   </link>
   <joint type="revolute" name="joint1">
      <parent link="base"/>
      <child link="joint1_jointbody"/>
      <origin xyz="0.0 0.0 0.1575" rpy="0.0 0.0 0.0"/>
      <axis xyz="0.0 0.0 1.0"/>
      <limit lower="-2.96706" upper="2.96706" effort="100" velocity="100"/>
   </joint>
   <joint type="fixed" name="joint1_offset">
      <parent link="joint1_jointbody"/>
      <child link="link1"/>
      <origin xyz="-0.0 -0.0 -0.0" rpy="0.0 0.0 0.0"/>
   </joint>
   <link name="link2">
      <inertial>
         <origin xyz="0.0003 0.059 0.042" rpy="1.5707963267948963 0.0 3.141592653589793"/>
         <mass value="6.35"/>
         <inertia ixx="0.0305" iyy="0.0304" izz="0.011" ixy="0" ixz="0" iyz="0"/>
      </inertial>
      <visual name="link_2_orange">
         <origin xyz="5.833243496088093e-06 -0.0013649111339534307 0.08664810682832555" rpy="-3.141308429776717 -1.3661334244729535 -1.5709650880838826"/>
         <geometry>
            <mesh filename="meshes/converted_link_2_orange_808080ff.obj"/>
         </geometry>
         <material name="Orange">
            <color rgba="1.0 0.423529411765 0.0392156862745 1.0"/>
         </material>
      </visual>
      <collision name="link_2_orange_col">
         <origin xyz="5.833243496088093e-06 -0.0013649111339534307 0.08664810682832555" rpy="-3.141308429776717 -1.3661334244729535 -1.5709650880838826"/>
         <geometry>
            <mesh filename="meshes/converted_link_2_orange_808080ff.obj"/>
         </geometry>
         <material name="Collision">
            <color rgba="0.0 0.0 0.2 1.0"/>
         </material>
      </collision>
      <visual name="link_2_grey">
         <origin xyz="0.00043793493861049083 0.10289616671473129 0.015210239136065893" rpy="0.001657667336488866 -1.5322290241696872 1.5691159451565273"/>
         <geometry>
            <mesh filename="meshes/converted_link_2_grey_808080ff.obj"/>
         </geometry>
         <material name="Grey">
            <color rgba="0.4 0.4 0.4 1.0"/>
         </material>
      </visual>
      <collision name="link_2_grey_col">
         <origin xyz="0.00043793493861049083 0.10289616671473129 0.015210239136065893" rpy="0.001657667336488866 -1.5322290241696872 1.5691159451565273"/>
         <geometry>
            <mesh filename="meshes/converted_link_2_grey_808080ff.obj"/>
         </geometry>
         <material name="Collision">
            <color rgba="0.0 0.0 0.2 1.0"/>
         </material>
      </collision>
   </link>
   <link name="joint2_jointbody">
      <inertial>
         <origin xyz="0.0 0.0 0.0" rpy="0.0 0.0 0.0"/>
         <mass value="0.001"/>
         <inertia ixx="1e-09" iyy="1e-09" izz="1e-09" ixy="0" ixz="0" iyz="0"/>
      </inertial>
   </link>
   <joint type="revolute" name="joint2">
      <parent link="link1"/>
      <child link="joint2_jointbody"/>
      <origin xyz="0.0 0.0 0.2025" rpy="1.5707963267948963 0.0 3.141592653589793"/>
      <axis xyz="0.0 0.0 1.0"/>
      <limit lower="-2.0944" upper="2.0944" effort="100" velocity="100"/>
   </joint>
   <joint type="fixed" name="joint2_offset">
      <parent link="joint2_jointbody"/>
      <child link="link2"/>
      <origin xyz="-0.0 -0.0 -0.0" rpy="0.0 0.0 0.0"/>
   </joint>
   <link name="link3">
      <inertial>
         <origin xyz="0.0 0.03 0.13" rpy="0.0 0.0 0.0"/>
         <mass value="3.5"/>
         <inertia ixx="0.025" iyy="0.0238" izz="0.0076" ixy="0" ixz="0" iyz="0"/>
      </inertial>
      <visual name="link_3">
         <origin xyz="1.4079955059051839e-06 0.032971200728359046 0.13639559733207407" rpy="0.0029220508029157433 0.2361384131999953 1.583292756861239"/>
         <geometry>
            <mesh filename="meshes/converted_link_3_808080ff.obj"/>
         </geometry>
         <material name="Grey">
            <color rgba="0.4 0.4 0.4 1.0"/>
         </material>
      </visual>
      <collision name="link_3_col">
         <origin xyz="1.4079955059051839e-06 0.032971200728359046 0.13639559733207407" rpy="0.0029220508029157433 0.2361384131999953 1.583292756861239"/>
         <geometry>
            <mesh filename="meshes/converted_link_3_808080ff.obj"/>
         </geometry>
         <material name="Collision">
            <color rgba="0.0 0.0 0.2 1.0"/>
         </material>
      </collision>
      <visual name="band">
         <origin xyz="-3.50527110797179e-05 -1.8385851986437544e-05 0.016549965935683288" rpy="-2.905385397814236 -1.570749028138471 -0.17498664727485913"/>
         <geometry>
            <mesh filename="meshes/converted_band_808080ff.obj"/>
         </geometry>
         <material name="White">
            <color rgba="1.0 1.0 1.0 1.0"/>
         </material>
      </visual>
      <collision name="band_col">
         <origin xyz="-3.50527110797179e-05 -1.8385851986437544e-05 0.016549965935683288" rpy="-2.905385397814236 -1.570749028138471 -0.17498664727485913"/>
         <geometry>
            <mesh filename="meshes/converted_band_808080ff.obj"/>
         </geometry>
         <material name="Collision">
            <color rgba="0.0 0.0 0.2 1.0"/>
         </material>
      </collision>
      <visual name="kuka">
         <origin xyz="1.0513736420380262e-06 -2.8644597444815276e-06 0.01613546649443194" rpy="1.6301255363357108 -1.5707963267948966 0.0"/>
         <geometry>
            <mesh filename="meshes/converted_kuka_808080ff.obj"/>
         </geometry>
         <material name="Black">
            <color rgba="0.0 0.0 0.0 0.0"/>
         </material>
      </visual>
      <collision name="kuka_col">
         <origin xyz="1.0513736420380262e-06 -2.8644597444815276e-06 0.01613546649443194" rpy="1.6301255363357108 -1.5707963267948966 0.0"/>
         <geometry>
            <mesh filename="meshes/converted_kuka_808080ff.obj"/>
         </geometry>
         <material name="Collision">
            <color rgba="0.0 0.0 0.2 1.0"/>
         </material>
      </collision>
   </link>
   <link name="joint3_jointbody">
      <inertial>
         <origin xyz="0.0 0.0 0.0" rpy="0.0 0.0 0.0"/>
         <mass value="0.001"/>
         <inertia ixx="1e-09" iyy="1e-09" izz="1e-09" ixy="0" ixz="0" iyz="0"/>
      </inertial>
   </link>
   <joint type="revolute" name="joint3">
      <parent link="link2"/>
      <child link="joint3_jointbody"/>
      <origin xyz="0.0 0.2045 0.0" rpy="1.5707963267948963 0.0 3.141592653589793"/>
      <axis xyz="0.0 0.0 1.0"/>
      <limit lower="-2.96706" upper="2.96706" effort="100" velocity="100"/>
   </joint>
   <joint type="fixed" name="joint3_offset">
      <parent link="joint3_jointbody"/>
      <child link="link3"/>
      <origin xyz="-0.0 -0.0 -0.0" rpy="0.0 0.0 0.0"/>
   </joint>
   <link name="link4">
      <inertial>
         <origin xyz="0.0 0.067 0.034" rpy="1.5707963267948963 0.0 0.0"/>
         <mass value="3.5"/>
         <inertia ixx="0.017" iyy="0.0164" izz="0.006" ixy="0" ixz="0" iyz="0"/>
      </inertial>
      <visual name="link_4_orange">
         <origin xyz="4.824980418423577e-06 0.007968855271483551 0.07976153475021944" rpy="3.14141233570375 -1.3520160965960935 -1.5708312876241155"/>
         <geometry>
            <mesh filename="meshes/converted_link_4_orange_808080ff.obj"/>
         </geometry>
         <material name="Orange">
            <color rgba="1.0 0.423529411765 0.0392156862745 1.0"/>
         </material>
      </visual>
      <collision name="link_4_orange_col">
         <origin xyz="4.824980418423577e-06 0.007968855271483551 0.07976153475021944" rpy="3.14141233570375 -1.3520160965960935 -1.5708312876241155"/>
         <geometry>
            <mesh filename="meshes/converted_link_4_orange_808080ff.obj"/>
         </geometry>
         <material name="Collision">
            <color rgba="0.0 0.0 0.2 1.0"/>
         </material>
      </collision>
      <visual name="link_4_grey">
         <origin xyz="-7.191555879988226e-07 0.09924633872981196 0.012969840121518902" rpy="0.0023581594407851014 -1.5072370203283618 1.5684105762133562"/>
         <geometry>
            <mesh filename="meshes/converted_link_4_grey_808080ff.obj"/>
         </geometry>
         <material name="Grey">
            <color rgba="0.4 0.4 0.4 1.0"/>
         </material>
      </visual>
      <collision name="link_4_grey_col">
         <origin xyz="-7.191555879988226e-07 0.09924633872981196 0.012969840121518902" rpy="0.0023581594407851014 -1.5072370203283618 1.5684105762133562"/>
         <geometry>
            <mesh filename="meshes/converted_link_4_grey_808080ff.obj"/>
         </geometry>
         <material name="Collision">
            <color rgba="0.0 0.0 0.2 1.0"/>
         </material>
      </collision>
   </link>
   <link name="joint4_jointbody">
      <inertial>
         <origin xyz="0.0 0.0 0.0" rpy="0.0 0.0 0.0"/>
         <mass value="0.001"/>
         <inertia ixx="1e-09" iyy="1e-09" izz="1e-09" ixy="0" ixz="0" iyz="0"/>
      </inertial>
   </link>
   <joint type="revolute" name="joint4">
      <parent link="link3"/>
      <child link="joint4_jointbody"/>
      <origin xyz="0.0 0.0 0.2155" rpy="1.5707963267948963 0.0 0.0"/>
      <axis xyz="0.0 0.0 1.0"/>
      <limit lower="-2.0944" upper="2.0944" effort="100" velocity="100"/>
   </joint>
   <joint type="fixed" name="joint4_offset">
      <parent link="joint4_jointbody"/>
      <child link="link4"/>
      <origin xyz="-0.0 -0.0 -0.0" rpy="0.0 0.0 0.0"/>
   </joint>
   <link name="link5">
      <inertial>
         <origin xyz="0.0001 0.021 0.076" rpy="0.0 0.0 0.0"/>
         <mass value="3.5"/>
         <inertia ixx="0.01" iyy="0.0087" izz="0.00449" ixy="0" ixz="0" iyz="0"/>
      </inertial>
      <visual name="link_5">
         <origin xyz="0.0038119492057678704 0.02870779349858075 0.09361014975338319" rpy="-0.0582855293349156 0.4061814878692964 1.5076633989230004"/>
         <geometry>
            <mesh filename="meshes/converted_link_5_808080ff.obj"/>
         </geometry>
         <material name="Grey">
            <color rgba="0.4 0.4 0.4 1.0"/>
         </material>
      </visual>
      <collision name="link_5_col">
         <origin xyz="0.0038119492057678704 0.02870779349858075 0.09361014975338319" rpy="-0.0582855293349156 0.4061814878692964 1.5076633989230004"/>
         <geometry>
            <mesh filename="meshes/converted_link_5_808080ff.obj"/>
         </geometry>
         <material name="Collision">
            <color rgba="0.0 0.0 0.2 1.0"/>
         </material>
      </collision>
      <visual name="band">
         <origin xyz="-3.50527110797179e-05 -1.8385851986437544e-05 0.016549965935683288" rpy="-2.905385397814236 -1.570749028138471 -0.17498664727485913"/>
         <geometry>
            <mesh filename="meshes/converted_band_808080ff.obj"/>
         </geometry>
         <material name="White">
            <color rgba="1.0 1.0 1.0 1.0"/>
         </material>
      </visual>
      <collision name="band_col">
         <origin xyz="-3.50527110797179e-05 -1.8385851986437544e-05 0.016549965935683288" rpy="-2.905385397814236 -1.570749028138471 -0.17498664727485913"/>
         <geometry>
            <mesh filename="meshes/converted_band_808080ff.obj"/>
         </geometry>
         <material name="Collision">
            <color rgba="0.0 0.0 0.2 1.0"/>
         </material>
      </collision>
      <visual name="kuka">
         <origin xyz="1.0513736420380262e-06 -2.8644597444815276e-06 0.01613546649443194" rpy="1.6301255363357108 -1.5707963267948966 0.0"/>
         <geometry>
            <mesh filename="meshes/converted_kuka_808080ff.obj"/>
         </geometry>
         <material name="Black">
            <color rgba="0.0 0.0 0.0 0.0"/>
         </material>
      </visual>

      <collision name="kuka_col">
         <origin xyz="1.0513736420380262e-06 -2.8644597444815276e-06 0.01613546649443194" rpy="1.6301255363357108 -1.5707963267948966 0.0"/>
         <geometry>
            <mesh filename="meshes/converted_kuka_808080ff.obj"/>
         </geometry>
         <material name="Collision">
            <color rgba="0.0 0.0 0.2 1.0"/>
         </material>
      </collision>
   </link>
   <link name="joint5_jointbody">
      <inertial>
         <origin xyz="0.0 0.0 0.0" rpy="0.0 0.0 0.0"/>
         <mass value="0.001"/>
         <inertia ixx="1e-09" iyy="1e-09" izz="1e-09" ixy="0" ixz="0" iyz="0"/>
      </inertial>
   </link>
   <joint type="revolute" name="joint5">
      <parent link="link4"/>
      <child link="joint5_jointbody"/>
      <origin xyz="0.0 0.1845 0.0" rpy="1.5707963267948963 0.0 3.141592653589793"/>
      <axis xyz="0.0 0.0 1.0"/>
      <limit lower="-2.96706" upper="2.96706" effort="100" velocity="100"/>
   </joint>
   <joint type="fixed" name="joint5_offset">
      <parent link="joint5_jointbody"/>
      <child link="link5"/>
      <origin xyz="-0.0 -0.0 -0.0" rpy="0.0 0.0 0.0"/>
   </joint>
   <link name="link6">
      <inertial>
         <origin xyz="0.0 0.0006 0.0004" rpy="1.5707963267948963 0.0 0.0"/>
         <mass value="1.8"/>
         <inertia ixx="0.0049" iyy="0.0047" izz="0.0036" ixy="0" ixz="0" iyz="0"/>
      </inertial>
      <visual name="link_6_orange">
         <origin xyz="-1.1732654423958586e-06 -0.03281057535697112 0.025841151571891964" rpy="3.1404471117136916 -1.0516466426619546 -1.5709595261648195"/>
         <geometry>
            <mesh filename="meshes/converted_link_6_orange_808080ff.obj"/>
         </geometry>
         <material name="Orange">
            <color rgba="1.0 0.423529411765 0.0392156862745 1.0"/>
         </material>
      </visual>
      <collision name="link_6_orange_col">
         <origin xyz="-1.1732654423958586e-06 -0.03281057535697112 0.025841151571891964" rpy="3.1404471117136916 -1.0516466426619546 -1.5709595261648195"/>
         <geometry>
            <mesh filename="meshes/converted_link_6_orange_808080ff.obj"/>
         </geometry>
         <material name="Collision">
            <color rgba="0.0 0.0 0.2 1.0"/>
         </material>
      </collision>
      <visual name="link_6_grey">
         <origin xyz="-4.166981000974423e-06 0.02953027794651189 -0.021364754377460885" rpy="3.1413656319557726 -0.9534988392118281 -1.5706843630687928"/>
         <geometry>
            <mesh filename="meshes/converted_link_6_grey_808080ff.obj"/>
         </geometry>
         <material name="Grey">
            <color rgba="0.4 0.4 0.4 1.0"/>
         </material>
      </visual>
      <collision name="link_6_grey_col">
         <origin xyz="-4.166981000974423e-06 0.02953027794651189 -0.021364754377460885" rpy="3.1413656319557726 -0.9534988392118281 -1.5706843630687928"/>
         <geometry>
            <mesh filename="meshes/converted_link_6_grey_808080ff.obj"/>
         </geometry>
         <material name="Collision">
            <color rgba="0.0 0.0 0.2 1.0"/>
         </material>
      </collision>
   </link>
   <link name="joint6_jointbody">
      <inertial>
         <origin xyz="0.0 0.0 0.0" rpy="0.0 0.0 0.0"/>
         <mass value="0.001"/>
         <inertia ixx="1e-09" iyy="1e-09" izz="1e-09" ixy="0" ixz="0" iyz="0"/>
      </inertial>
   </link>
   <joint type="revolute" name="joint6">
      <parent link="link5"/>
      <child link="joint6_jointbody"/>
      <origin xyz="0.0 0.0 0.2155" rpy="1.5707963267948963 0.0 0.0"/>
      <axis xyz="0.0 0.0 1.0"/>
      <limit lower="-2.0944" upper="2.0944" effort="100" velocity="100"/>
   </joint>
   <joint type="fixed" name="joint6_offset">
      <parent link="joint6_jointbody"/>
      <child link="link6"/>
      <origin xyz="-0.0 -0.0 -0.0" rpy="0.0 0.0 0.0"/>
   </joint>
   <link name="link7">
      <inertial>
         <origin xyz="0.0 0.0 0.02" rpy="0.0 0.0 0.0"/>
         <mass value="1.2"/>
         <inertia ixx="0.001" iyy="0.001" izz="0.001" ixy="0" ixz="0" iyz="0"/>
      </inertial>
      <visual name="link_7">
         <origin xyz="-9.661076849603895e-06 -9.153380335809451e-07 0.01686968091357946" rpy="1.5715274960314827 -1.5704055271954749 2.523536934972981e-13"/>
         <geometry>
            <mesh filename="meshes/converted_link_7_808080ff.obj"/>
         </geometry>
         <material name="Grey">
            <color rgba="0.4 0.4 0.4 1.0"/>
         </material>
      </visual>
      <collision name="link_7_col">
         <origin xyz="-9.661076849603895e-06 -9.153380335809451e-07 0.01686968091357946" rpy="1.5715274960314827 -1.5704055271954749 2.523536934972981e-13"/>
         <geometry>
            <mesh filename="meshes/converted_link_7_808080ff.obj"/>
         </geometry>
         <material name="Collision">
            <color rgba="0.0 0.0 0.2 1.0"/>
         </material>
      </collision>
   </link>
   <link name="joint7_jointbody">
      <inertial>
         <origin xyz="0.0 0.0 0.0" rpy="0.0 0.0 0.0"/>
         <mass value="0.001"/>
         <inertia ixx="1e-09" iyy="1e-09" izz="1e-09" ixy="0" ixz="0" iyz="0"/>
      </inertial>
   </link>
   <joint type="revolute" name="joint7">
      <parent link="link6"/>
      <child link="joint7_jointbody"/>
      <origin xyz="0.0 0.081 0.0" rpy="1.5707963267948963 0.0 3.141592653589793"/>
      <axis xyz="0.0 0.0 1.0"/>
      <limit lower="-3.05433" upper="3.05433" effort="100" velocity="100"/>
   </joint>
   <joint type="fixed" name="joint7_offset">
      <parent link="joint7_jointbody"/>
      <child link="link7"/>
      <origin xyz="-0.0 -0.0 -0.0" rpy="0.0 0.0 0.0"/>
   </joint>
</robot>
